2020-08-31 21:49:05,887 INFO: Microblog startup [in C:\Users\Marta\PycharmProjects\Pyth-Course-FlaskMicroblog\app\__init__.py:51]
2020-08-31 21:49:19,796 ERROR: Exception on /edit_profile [POST] [in C:\Users\Marta\Anaconda3\lib\site-packages\flask\app.py:1761]
Traceback (most recent call last):
  File "C:\Users\Marta\Anaconda3\lib\site-packages\sqlalchemy\engine\base.py", line 1278, in _execute_context
    cursor, statement, parameters, context
  File "C:\Users\Marta\Anaconda3\lib\site-packages\sqlalchemy\engine\default.py", line 593, in do_execute
    cursor.execute(statement, parameters)
sqlite3.IntegrityError: UNIQUE constraint failed: user.username

The above exception was the direct cause of the following exception:

Traceback (most recent call last):
  File "C:\Users\Marta\Anaconda3\lib\site-packages\flask\app.py", line 2292, in wsgi_app
    response = self.full_dispatch_request()
  File "C:\Users\Marta\Anaconda3\lib\site-packages\flask\app.py", line 1815, in full_dispatch_request
    rv = self.handle_user_exception(e)
  File "C:\Users\Marta\Anaconda3\lib\site-packages\flask\app.py", line 1718, in handle_user_exception
    reraise(exc_type, exc_value, tb)
  File "C:\Users\Marta\Anaconda3\lib\site-packages\flask\_compat.py", line 35, in reraise
    raise value
  File "C:\Users\Marta\Anaconda3\lib\site-packages\flask\app.py", line 1813, in full_dispatch_request
    rv = self.dispatch_request()
  File "C:\Users\Marta\Anaconda3\lib\site-packages\flask\app.py", line 1799, in dispatch_request
    return self.view_functions[rule.endpoint](**req.view_args)
  File "C:\Users\Marta\Anaconda3\lib\site-packages\flask_login\utils.py", line 272, in decorated_view
    return func(*args, **kwargs)
  File "C:\Users\Marta\PycharmProjects\Pyth-Course-FlaskMicroblog\app\routes.py", line 87, in edit_profile
    db.session.commit()
  File "C:\Users\Marta\Anaconda3\lib\site-packages\sqlalchemy\orm\scoping.py", line 163, in do
    return getattr(self.registry(), name)(*args, **kwargs)
  File "C:\Users\Marta\Anaconda3\lib\site-packages\sqlalchemy\orm\session.py", line 1042, in commit
    self.transaction.commit()
  File "C:\Users\Marta\Anaconda3\lib\site-packages\sqlalchemy\orm\session.py", line 504, in commit
    self._prepare_impl()
  File "C:\Users\Marta\Anaconda3\lib\site-packages\sqlalchemy\orm\session.py", line 483, in _prepare_impl
    self.session.flush()
  File "C:\Users\Marta\Anaconda3\lib\site-packages\sqlalchemy\orm\session.py", line 2523, in flush
    self._flush(objects)
  File "C:\Users\Marta\Anaconda3\lib\site-packages\sqlalchemy\orm\session.py", line 2664, in _flush
    transaction.rollback(_capture_exception=True)
  File "C:\Users\Marta\Anaconda3\lib\site-packages\sqlalchemy\util\langhelpers.py", line 69, in __exit__
    exc_value, with_traceback=exc_tb,
  File "C:\Users\Marta\Anaconda3\lib\site-packages\sqlalchemy\util\compat.py", line 178, in raise_
    raise exception
  File "C:\Users\Marta\Anaconda3\lib\site-packages\sqlalchemy\orm\session.py", line 2624, in _flush
    flush_context.execute()
  File "C:\Users\Marta\Anaconda3\lib\site-packages\sqlalchemy\orm\unitofwork.py", line 422, in execute
    rec.execute(self)
  File "C:\Users\Marta\Anaconda3\lib\site-packages\sqlalchemy\orm\unitofwork.py", line 589, in execute
    uow,
  File "C:\Users\Marta\Anaconda3\lib\site-packages\sqlalchemy\orm\persistence.py", line 236, in save_obj
    update,
  File "C:\Users\Marta\Anaconda3\lib\site-packages\sqlalchemy\orm\persistence.py", line 995, in _emit_update_statements
    statement, multiparams
  File "C:\Users\Marta\Anaconda3\lib\site-packages\sqlalchemy\engine\base.py", line 1014, in execute
    return meth(self, multiparams, params)
  File "C:\Users\Marta\Anaconda3\lib\site-packages\sqlalchemy\sql\elements.py", line 298, in _execute_on_connection
    return connection._execute_clauseelement(self, multiparams, params)
  File "C:\Users\Marta\Anaconda3\lib\site-packages\sqlalchemy\engine\base.py", line 1133, in _execute_clauseelement
    distilled_params,
  File "C:\Users\Marta\Anaconda3\lib\site-packages\sqlalchemy\engine\base.py", line 1318, in _execute_context
    e, statement, parameters, cursor, context
  File "C:\Users\Marta\Anaconda3\lib\site-packages\sqlalchemy\engine\base.py", line 1512, in _handle_dbapi_exception
    sqlalchemy_exception, with_traceback=exc_info[2], from_=e
  File "C:\Users\Marta\Anaconda3\lib\site-packages\sqlalchemy\util\compat.py", line 178, in raise_
    raise exception
  File "C:\Users\Marta\Anaconda3\lib\site-packages\sqlalchemy\engine\base.py", line 1278, in _execute_context
    cursor, statement, parameters, context
  File "C:\Users\Marta\Anaconda3\lib\site-packages\sqlalchemy\engine\default.py", line 593, in do_execute
    cursor.execute(statement, parameters)
sqlalchemy.exc.IntegrityError: (sqlite3.IntegrityError) UNIQUE constraint failed: user.username
[SQL: UPDATE user SET username=?, about_me=? WHERE user.id = ?]
[parameters: ('susan', 'Jestem kotem', 4)]
(Background on this error at: http://sqlalche.me/e/13/gkpj)
2020-08-31 22:07:35,742 INFO: Microblog startup [in C:\Users\Marta\PycharmProjects\Pyth-Course-FlaskMicroblog\app\__init__.py:51]
2020-09-02 00:03:26,401 INFO: Microblog startup [in C:\Users\Marta\PycharmProjects\Pyth-Course-FlaskMicroblog\app\__init__.py:51]
2020-09-02 00:03:38,162 INFO: Microblog startup [in C:\Users\Marta\PycharmProjects\Pyth-Course-FlaskMicroblog\app\__init__.py:51]
2020-09-02 00:24:30,330 INFO: Microblog startup [in C:\Users\Marta\PycharmProjects\Pyth-Course-FlaskMicroblog\app\__init__.py:51]
